Traceback (most recent call last):
  File "/usr/share/miniconda3/envs/computo/lib/python3.9/site-packages/jupyter_cache/executors/utils.py", line 51, in single_nb_execution
    executenb(
  File "/usr/share/miniconda3/envs/computo/lib/python3.9/site-packages/nbclient/client.py", line 1204, in execute
    return NotebookClient(nb=nb, resources=resources, km=km, **kwargs).execute()
  File "/usr/share/miniconda3/envs/computo/lib/python3.9/site-packages/nbclient/util.py", line 84, in wrapped
    return just_run(coro(*args, **kwargs))
  File "/usr/share/miniconda3/envs/computo/lib/python3.9/site-packages/nbclient/util.py", line 62, in just_run
    return loop.run_until_complete(coro)
  File "/usr/share/miniconda3/envs/computo/lib/python3.9/asyncio/base_events.py", line 642, in run_until_complete
    return future.result()
  File "/usr/share/miniconda3/envs/computo/lib/python3.9/site-packages/nbclient/client.py", line 663, in async_execute
    await self.async_execute_cell(
  File "/usr/share/miniconda3/envs/computo/lib/python3.9/site-packages/nbclient/client.py", line 965, in async_execute_cell
    await self._check_raise_for_error(cell, cell_index, exec_reply)
  File "/usr/share/miniconda3/envs/computo/lib/python3.9/site-packages/nbclient/client.py", line 862, in _check_raise_for_error
    raise CellExecutionError.from_cell_and_msg(cell, exec_reply_content)
nbclient.exceptions.CellExecutionError: An error occurred while executing the following cell:
------------------
from myst_nb import glue
import matplotlib.pyplot as plt
matplotlib.use('agg')
import os

from surfnet.prepare_data import download_data
from surfnet.track import default_args as args

# download frames and detections from a given deep detector model
download_data()

# prepare arguments
args.external_detections = True
args.data_dir = 'data/external_detections/part_1_segment_0'
args.output_dir = 'surfnet/results'
args.noise_covariances_path = 'surfnet/data/tracking_parameters'
args.confidence_threshold = 0.5
args.algorithm = 'EKF'
args.ratio = 4
args.display = 0
------------------

[0;31m---------------------------------------------------------------------------[0m
[0;31mNameError[0m                                 Traceback (most recent call last)
Input [0;32mIn [1][0m, in [0;36m<cell line: 3>[0;34m()[0m
[1;32m      1[0m [38;5;28;01mfrom[39;00m [38;5;21;01mmyst_nb[39;00m [38;5;28;01mimport[39;00m glue
[1;32m      2[0m [38;5;28;01mimport[39;00m [38;5;21;01mmatplotlib[39;00m[38;5;21;01m.[39;00m[38;5;21;01mpyplot[39;00m [38;5;28;01mas[39;00m [38;5;21;01mplt[39;00m
[0;32m----> 3[0m [43mmatplotlib[49m[38;5;241m.[39muse([38;5;124m'[39m[38;5;124magg[39m[38;5;124m'[39m)
[1;32m      4[0m [38;5;28;01mimport[39;00m [38;5;21;01mos[39;00m
[1;32m      6[0m [38;5;28;01mfrom[39;00m [38;5;21;01msurfnet[39;00m[38;5;21;01m.[39;00m[38;5;21;01mprepare_data[39;00m [38;5;28;01mimport[39;00m download_data

[0;31mNameError[0m: name 'matplotlib' is not defined
NameError: name 'matplotlib' is not defined

